<?xml version="1.0"?>
<robot name="micromouse" xmlns:xacro="http://www.ros.org/wiki/xacro">

    <!-- Constants for robot -->
    <xacro:property name="rotation_90" value="1.57079632679"/>
    <xacro:property name="scale_chassis" value="0.25"/>
    <xacro:property name="scale_wheel" value="0.03"/>
    <xacro:property name="mass_chassis" value="1.2"/>
    <xacro:property name="mass_wheel" value="0.3"/>
    <xacro:property name="mass_castor" value="0.2"/>
    <xacro:property name="radius_castor" value="0.005"/>
    <xacro:property name="wheel_pos_x" value="0.026"/>
    <xacro:property name="wheel_pos_y" value="-0.016"/>
    <xacro:property name="castor_pos_y" value="0.025"/>
    
    <!-- Import all Gazebo-customization elements, including Gazebo colors -->
    <xacro:include filename="$(find micromouse)/urdf/micromouse_robot.gazebo" />

    <xacro:macro name="wheel_link" params="name">
        <link name="${name}_wheel_link">
            <visual>
                <origin xyz="0 0 0" rpy="0.0 ${rotation_90} 0.0"/>
                <geometry>
                    <cylinder radius="0.01" length="0.00425"/>
                </geometry>
            </visual>
            <collision>
                <origin xyz="0 0 0" rpy="0.0 ${rotation_90} 0.0"/>
                <geometry>
                    <cylinder radius="0.01" length="0.00425"/>
                </geometry>
            </collision>
            <inertial>
                <mass value="${mass_wheel}" />
                <inertia ixx="0.000305" ixy="0.0032" ixz="0.0" iyy="0.009" iyz="8e-6" izz="0.00031" />
            </inertial>
        </link>
    </xacro:macro>

    <link name="dummy"/>
    <link name="base_link">
        <visual>
            <origin xyz="0.0 0.0 0.0" rpy="${rotation_90} 0.0 0.0"/>
            <geometry>
                <mesh filename="package://micromouse/models/chassis/micromouse.obj" scale="${scale_chassis} ${scale_chassis} ${scale_chassis}"/>
            </geometry>
        </visual>
        <collision>
            <origin xyz="0.0 0.0 0.0" rpy="${rotation_90} 0.0 0.0"/>
            <geometry>
                <box size="0.045 0.004 0.075"/>
            </geometry>
        </collision>
        <inertial>
            <mass value="${mass_chassis}" />
            <inertia ixx="0.012" ixy="1.5e-6" ixz="0.0" iyy="0.01" iyz="0.0" izz="0.12" />
        </inertial>
    </link>

    <xacro:wheel_link name="left"/>
    <xacro:wheel_link name="right"/>

    <link name="castor_link">
        <visual>
            <geometry>
                <sphere radius="${radius_castor}"/>
            </geometry>
        </visual>
        <collision>
            <geometry>
                <sphere radius="${radius_castor}"/>
            </geometry>
            <inertial>
                <origin xyz="0.0 0.0 0.0" rpy="0.0 0.0 0.0"/>
                <mass value="${mass_castor}"/>
                <inertia ixx="0.002" ixy="0.0" ixz="0.0" iyy="0.002" iyz="0.0" izz="0.002"/>
            </inertial>
        </collision>
    </link>

    <joint name="left_wheel" type="continuous">
        <parent link="base_link"/>
        <child link="left_wheel_link"/>
        <axis xyz="1 0 0"/>
        <origin xyz="${wheel_pos_x} ${wheel_pos_y} 0.0" rpy="0 0 0"/>
        <limit effort="1000.0" velocity="100.0"/>
    </joint>
    <joint name="right_wheel" type="continuous">
        <parent link="base_link"/>
        <child link="right_wheel_link"/>
        <axis xyz="1 0 0"/>
        <origin xyz="-${wheel_pos_x} ${wheel_pos_y} 0.0" rpy="0 0 0"/>
        <limit effort="1000.0" velocity="100.0"/>
    </joint>
    <joint name="castor_wheel" type="fixed">
        <parent link="base_link"/>
        <child link="castor_link"/>
        <origin xyz="0 ${castor_pos_y} -0.006"/>
    </joint>

    <joint name="dummy_joint" type="fixed">
        <parent link="dummy"/>
        <child link="base_link"/>
    </joint>
    

    <!-- Transmission is important to link the joints and the controller -->
    <transmission name="left_wheel_trans">
        <type>transmission_interface/SimpleTransmission</type>
        <joint name="left_wheel">
            <hardwareInterface>hardware_interface/VelocityJointInterface</hardwareInterface>
        </joint>
        <actuator name="left_wheel_motor">
            <hardwareInterface>EffortJointInterface</hardwareInterface>
            <mechanicalReduction>1</mechanicalReduction>
        </actuator>
    </transmission>

    <transmission name="right_wheel_trans">
        <type>transmission_interface/SimpleTransmission</type>
        <joint name="right_wheel">
            <hardwareInterface>hardware_interface/VelocityJointInterface</hardwareInterface>
        </joint>
        <actuator name="right_wheel_motor">
            <hardwareInterface>EffortJointInterface</hardwareInterface>
            <mechanicalReduction>1</mechanicalReduction>
        </actuator>
    </transmission>

</robot>