<?xml version="1.0"?>
<robot name="micromouse" xmlns:xacro="http://www.ros.org/wiki/xacro">

    <!-- Constants for robot -->
    <xacro:property name="rotation_90" value="1.57079632679"/>
    <xacro:property name="scale_chassis" value="0.25"/>
    <xacro:property name="scale_wheel" value="0.03"/>
    <xacro:property name="mass_chassis" value="0.5"/>
    <xacro:property name="mass_wheel" value="0.01"/>
    <xacro:property name="mass_castor" value="0.2"/>
    <xacro:property name="radius_castor" value="0.005"/>
    <xacro:property name="wheel_pos_x" value="0.026"/>
    <xacro:property name="wheel_pos_y" value="-0.016"/>
    <xacro:property name="castor_pos_y" value="0.025"/>
    
    <!-- Import all Gazebo-customization elements, including Gazebo colors -->
    <xacro:include filename="$(find micromouse)/urdf/micromouse_robot.gazebo" />

    <xacro:macro name="wheel_link" params="name *origin">
        <link name="${name}_wheel_link">
            <visual>
                <xacro:insert_block name="origin"/>
                <geometry>
                    <cylinder radius="0.02" length="0.01"/>
                </geometry>
            </visual>
            <collision>
                <xacro:insert_block name="origin"/>
                <geometry>
                    <cylinder radius="0.02" length="0.01"/>
                </geometry>
            </collision>
            <inertial>
                <mass value="${mass_wheel}" />
                <inertia ixx="2.3e-06" ixy="0" ixz="0.0" iyy="2.3e-06" iyz="0" izz="4.5e-06" />
            </inertial>
        </link>
    </xacro:macro>

    
    <link name="base_link">
        <visual>
            <origin xyz="0.0 0.0 0.005" rpy="0.0 0.0 0.0"/>
            <geometry>
                <box size="0.07 0.07 0.02"/>
            </geometry>
        </visual>
        <collision>
            <origin xyz="0.0 0.0 0.005" rpy="0.0 0.0 0.0"/>
            <geometry>
                <box size="0.07 0.07 0.02"/>
            </geometry>
        </collision>
        <inertial>
            <mass value="${mass_chassis}" />
            <inertia ixx="0.00022083" ixy="0.0" ixz="0.0" iyy="0.00022083" iyz="0.0" izz="0.00040833" />
        </inertial>
    </link>

    <xacro:wheel_link name="left">
        <origin xyz="0.02 0.0 0.0" rpy="0.0 ${rotation_90} 0.0"/>
    </xacro:wheel_link>
    <xacro:wheel_link name="right">
        <origin xyz="-0.02 0.0 0.0" rpy="0.0 ${rotation_90} 0.0"/>
    </xacro:wheel_link>

    <link name="castor_link">
        <visual>
            <geometry>
                <sphere radius="${radius_castor}"/>
            </geometry>
        </visual>
        <collision>
            <geometry>
                <sphere radius="${radius_castor}"/>
            </geometry>
            <inertial>
                <origin xyz="0.0 0.03 -0.02" rpy="0.0 0.0 0.0"/>
                <mass value="${mass_castor}"/>
                <inertia ixx="0.002" ixy="0.0" ixz="0.0" iyy="0.002" iyz="0.0" izz="0.002"/>
            </inertial>
        </collision>
    </link>

    <joint name="left_wheel" type="continuous">
        <parent link="base_link"/>
        <child link="left_wheel_link"/>
        <axis xyz="1 0 0"/>
        <origin xyz="${wheel_pos_x} ${wheel_pos_y} 0.0" rpy="0 0 0"/>
        <limit effort="-1" velocity="100.0"/>
        <dynamics damping="0.01" friction="0.0"/>
    </joint>
    <joint name="right_wheel" type="continuous">
        <parent link="base_link"/>
        <child link="right_wheel_link"/>
        <axis xyz="1 0 0"/>
        <origin xyz="-${wheel_pos_x} ${wheel_pos_y} 0.0" rpy="0 0 0"/>
        <limit effort="-1" velocity="100.0"/>
        <dynamics damping="0.01" friction="0.0"/>
    </joint>
    <joint name="castor_wheel" type="fixed">
        <parent link="base_link"/>
        <child link="castor_link"/>
        <origin xyz="0 ${castor_pos_y} -0.006"/>
    </joint>

    <!-- Transmission is important to link the joints and the controller -->
    <transmission name="left_wheel_trans">
        <type>transmission_interface/SimpleTransmission</type>
        <joint name="left_wheel">
            <hardwareInterface>hardware_interface/VelocityJointInterface</hardwareInterface>
        </joint>
        <actuator name="left_wheel_motor">
            <hardwareInterface>EffortJointInterface</hardwareInterface>
            <mechanicalReduction>1</mechanicalReduction>
        </actuator>
    </transmission>

    <transmission name="right_wheel_trans">
        <type>transmission_interface/SimpleTransmission</type>
        <joint name="right_wheel">
            <hardwareInterface>hardware_interface/VelocityJointInterface</hardwareInterface>
        </joint>
        <actuator name="right_wheel_motor">
            <hardwareInterface>EffortJointInterface</hardwareInterface>
            <mechanicalReduction>1</mechanicalReduction>
        </actuator>
    </transmission>

</robot>